[2024-08-15 14:39:44,988] {taskinstance.py:851} INFO - Dependencies all met for <TaskInstance: dag_with_postgres_hooks_v04.postgres_to_s3 2022-05-22T00:00:00+00:00 [queued]>
[2024-08-15 14:39:45,044] {taskinstance.py:851} INFO - Dependencies all met for <TaskInstance: dag_with_postgres_hooks_v04.postgres_to_s3 2022-05-22T00:00:00+00:00 [queued]>
[2024-08-15 14:39:45,045] {taskinstance.py:1042} INFO - 
--------------------------------------------------------------------------------
[2024-08-15 14:39:45,046] {taskinstance.py:1043} INFO - Starting attempt 5 of 6
[2024-08-15 14:39:45,063] {taskinstance.py:1044} INFO - 
--------------------------------------------------------------------------------
[2024-08-15 14:39:45,105] {taskinstance.py:1063} INFO - Executing <Task(PythonOperator): postgres_to_s3> on 2022-05-22T00:00:00+00:00
[2024-08-15 14:39:45,155] {standard_task_runner.py:52} INFO - Started process 38148 to run task
[2024-08-15 14:39:45,195] {standard_task_runner.py:76} INFO - Running: ['airflow', 'tasks', 'run', 'dag_with_postgres_hooks_v04', 'postgres_to_s3', '2022-05-22T00:00:00+00:00', '--job-id', '12901', '--pool', 'default_pool', '--raw', '--subdir', 'DAGS_FOLDER/dag_with_postgres_hooks.py', '--cfg-path', '/tmp/tmpuy7u3_nb', '--error-file', '/tmp/tmp00rfzt6u']
[2024-08-15 14:39:45,294] {standard_task_runner.py:77} INFO - Job 12901: Subtask postgres_to_s3
[2024-08-15 14:39:46,636] {logging_mixin.py:104} INFO - Running <TaskInstance: dag_with_postgres_hooks_v04.postgres_to_s3 2022-05-22T00:00:00+00:00 [running]> on host 799b1e36e3f1
[2024-08-15 14:39:47,200] {taskinstance.py:1257} INFO - Exporting the following env vars:
AIRFLOW_CTX_DAG_OWNER=coder2j
AIRFLOW_CTX_DAG_ID=dag_with_postgres_hooks_v04
AIRFLOW_CTX_TASK_ID=postgres_to_s3
AIRFLOW_CTX_EXECUTION_DATE=2022-05-22T00:00:00+00:00
AIRFLOW_CTX_DAG_RUN_ID=scheduled__2022-05-22T00:00:00+00:00
[2024-08-15 14:39:47,383] {taskinstance.py:1455} ERROR - The conn_id `postgres_localhost` isn't defined
Traceback (most recent call last):
  File "/home/airflow/.local/lib/python3.6/site-packages/airflow/models/taskinstance.py", line 1112, in _run_raw_task
    self._prepare_and_execute_task_with_callbacks(context, task)
  File "/home/airflow/.local/lib/python3.6/site-packages/airflow/models/taskinstance.py", line 1285, in _prepare_and_execute_task_with_callbacks
    result = self._execute_task(context, task_copy)
  File "/home/airflow/.local/lib/python3.6/site-packages/airflow/models/taskinstance.py", line 1315, in _execute_task
    result = task_copy.execute(context=context)
  File "/home/airflow/.local/lib/python3.6/site-packages/airflow/operators/python.py", line 117, in execute
    return_value = self.execute_callable()
  File "/home/airflow/.local/lib/python3.6/site-packages/airflow/operators/python.py", line 128, in execute_callable
    return self.python_callable(*self.op_args, **self.op_kwargs)
  File "/opt/airflow/dags/dag_with_postgres_hooks.py", line 22, in postgres_to_s3
    conn = hook.get_conn()
  File "/home/airflow/.local/lib/python3.6/site-packages/airflow/providers/postgres/hooks/postgres.py", line 83, in get_conn
    conn = self.connection or self.get_connection(conn_id)
  File "/home/airflow/.local/lib/python3.6/site-packages/airflow/hooks/base.py", line 63, in get_connection
    conn = Connection.get_connection_from_secrets(conn_id)
  File "/home/airflow/.local/lib/python3.6/site-packages/airflow/models/connection.py", line 354, in get_connection_from_secrets
    raise AirflowNotFoundException(f"The conn_id `{conn_id}` isn't defined")
airflow.exceptions.AirflowNotFoundException: The conn_id `postgres_localhost` isn't defined
[2024-08-15 14:39:47,412] {taskinstance.py:1503} INFO - Marking task as UP_FOR_RETRY. dag_id=dag_with_postgres_hooks_v04, task_id=postgres_to_s3, execution_date=20220522T000000, start_date=20240815T143944, end_date=20240815T143947
[2024-08-15 14:39:47,587] {local_task_job.py:146} INFO - Task exited with return code 1
